(masclet-imperi) PS C:\Proyectos\claude\masclet-imperi-web\backend\docker\compose> docker ps
>>
CONTAINER ID   IMAGE                COMMAND                  CREATED          STATUS                          PORTS                                      NAMES
de575ee0ef93   masclet-imperi-api   "uvicorn app.main:ap…"   10 minutes ago   Restarting (3) 16 seconds ago                                              masclet-api
fa5feb2d4826   traefik:v2.10        "/entrypoint.sh --ap…"   10 minutes ago   Up 10 minutes                   0.0.0.0:80->80/tcp, 0.0.0.0:443->443/tcp   masclet-traefik
1e71f11a0595   masclet-imperi-db    "docker-entrypoint.s…"   10 minutes ago   Up 10 minutes (healthy)         5432/tcp                                   masclet-db
779510b696c7   redis:alpine         "docker-entrypoint.s…"   10 minutes ago   Up 10 minutes                   6379/tcp                                   masclet-cache
36cd3972ce5b   redis:alpine         "docker-entrypoint.s…"   2 days ago       Up 9 hours (healthy)            0.0.0.0:6379->6379/tcp                     masclet_imperi_cache
(masclet-imperi) PS C:\Proyectos\claude\masclet-imperi-web\backend\docker\compose> docker logs masclet-db
crond 4.5 dillon's cron daemon, started with loglevel debug
Synchronizing /etc/crontabs
User root Entry */15    *       *       *       *       run-parts /etc/periodic/15min
100000000000000100000000000000100000000000000100000000000000
111111111111111111111111
11111111111111111111111111111111
111111111111
3f 3f 3f 3f 3f 3f 3f
    Command run-parts /etc/periodic/15min

User root Entry 0       *       *       *       *       run-parts /etc/periodic/hourly
100000000000000000000000000000000000000000000000000000000000
111111111111111111111111
11111111111111111111111111111111
111111111111
3f 3f 3f 3f 3f 3f 3f
    Command run-parts /etc/periodic/hourly

User root Entry 0       2       *       *       *       run-parts /etc/periodic/daily
100000000000000000000000000000000000000000000000000000000000
001000000000000000000000
11111111111111111111111111111111
111111111111
3f 3f 3f 3f 3f 3f 3f
    Command run-parts /etc/periodic/daily

User root Entry 0       3       *       *       6       run-parts /etc/periodic/weekly
100000000000000000000000000000000000000000000000000000000000
000100000000000000000000
11111111111111111111111111111111
111111111111
 0  0  0  0  0  0 3f
    Command run-parts /etc/periodic/weekly

User root Entry 0       5       1       *       *       run-parts /etc/periodic/monthly
100000000000000000000000000000000000000000000000000000000000
000001000000000000000000
01000000000000000000000000000000
111111111111
3f 3f 3f 3f 3f 3f 3f
    Command run-parts /etc/periodic/monthly

Synchronizing /etc/cron.d
TestStartup for FILE /etc/crontabs/root USER root:
    LINE run-parts /etc/periodic/15min
    LINE run-parts /etc/periodic/hourly
    LINE run-parts /etc/periodic/daily
    LINE run-parts /etc/periodic/weekly
    LINE run-parts /etc/periodic/monthly

PostgreSQL Database directory appears to contain a database; Skipping initialization

2025-02-17 20:42:52.814 UTC [1] LOG:  starting PostgreSQL 17.3 on x86_64-pc-linux-musl, compiled by gcc (Alpine 14.2.0) 14.2.0, 64-bit
2025-02-17 20:42:52.814 UTC [1] LOG:  listening on IPv4 address "0.0.0.0", port 5432
2025-02-17 20:42:52.814 UTC [1] LOG:  listening on IPv6 address "::", port 5432
2025-02-17 20:42:52.821 UTC [1] LOG:  listening on Unix socket "/var/run/postgresql/.s.PGSQL.5432"
2025-02-17 20:42:52.847 UTC [29] LOG:  database system was shut down at 2025-02-17 19:51:15 UTC
2025-02-17 20:42:52.897 UTC [1] LOG:  database system is ready to accept connections
Wakeup dt=9
TestJobs() database.c:974
Wakeup dt=60
TestJobs() database.c:974
Wakeup dt=60
TestJobs() database.c:974
scheduled: user root run-parts /etc/periodic/15min
FILE /etc/crontabs/root USER root PID 123 run-parts /etc/periodic/15min
child running: run-parts /etc/periodic/15min
exit status 0 from user root run-parts /etc/periodic/15min
Wakeup dt=60
TestJobs() database.c:974
Wakeup dt=60
TestJobs() database.c:974
2025-02-17 20:47:52.938 UTC [27] LOG:  checkpoint starting: time
2025-02-17 20:47:52.992 UTC [27] LOG:  checkpoint complete: wrote 3 buffers (0.0%); 0 WAL file(s) added, 0 removed, 0 recycled; write=0.011 s, sync=0.005 s, total=0.054 s; sync files=2, longest=0.003 s, average=0.003 s; distance=0 kB, estimate=0 kB; lsn=0/1954FF0, redo lsn=0/1954F98
Wakeup dt=60
TestJobs() database.c:974
Wakeup dt=60
TestJobs() database.c:974
Wakeup dt=60
TestJobs() database.c:974
Wakeup dt=60
TestJobs() database.c:974
Wakeup dt=60
TestJobs() database.c:974
Wakeup dt=60
TestJobs() database.c:974
(masclet-imperi) PS C:\Proyectos\claude\masclet-imperi-web\backend\docker\compose> docker logs masclet-api
INFO:     Started server process [1]
INFO:     Waiting for application startup.
ERROR:    Traceback (most recent call last):
  File "/usr/local/lib/python3.13/site-packages/tortoise/connection.py", line 122, in get
    return storage[conn_alias]
           ~~~~~~~^^^^^^^^^^^^
KeyError: 'default'

During handling of the above exception, another exception occurred:

Traceback (most recent call last):
  File "/usr/local/lib/python3.13/site-packages/starlette/routing.py", line 677, in lifespan
    async with self.lifespan_context(app) as maybe_state:
               ~~~~~~~~~~~~~~~~~~~~~^^^^^
  File "/usr/local/lib/python3.13/site-packages/starlette/routing.py", line 566, in __aenter__
    await self._router.startup()
  File "/usr/local/lib/python3.13/site-packages/starlette/routing.py", line 654, in startup
    await handler()
  File "/usr/local/lib/python3.13/site-packages/tortoise/contrib/fastapi/__init__.py", line 263, in init_orm
    await orm.init_orm()
  File "/usr/local/lib/python3.13/site-packages/tortoise/contrib/fastapi/__init__.py", line 138, in init_orm
    await Tortoise.init(
    ...<7 lines>...
    )
  File "/usr/local/lib/python3.13/site-packages/tortoise/__init__.py", line 512, in init
    await connections._init(connections_config, _create_db)
  File "/usr/local/lib/python3.13/site-packages/tortoise/connection.py", line 33, in _init
    await self._init_connections()
  File "/usr/local/lib/python3.13/site-packages/tortoise/connection.py", line 94, in _init_connections
    connection: "BaseDBAsyncClient" = self.get(alias)
                                      ~~~~~~~~^^^^^^^
  File "/usr/local/lib/python3.13/site-packages/tortoise/connection.py", line 124, in get
    connection: BaseDBAsyncClient = self._create_connection(conn_alias)
                                    ~~~~~~~~~~~~~~~~~~~~~~~^^^^^^^^^^^^
  File "/usr/local/lib/python3.13/site-packages/tortoise/connection.py", line 102, in _create_connection
    client_class = self._discover_client_class(db_info)
  File "/usr/local/lib/python3.13/site-packages/tortoise/connection.py", line 71, in _discover_client_class
    engine_module = importlib.import_module(engine_str)
  File "/usr/local/lib/python3.13/importlib/__init__.py", line 88, in import_module
    return _bootstrap._gcd_import(name[level:], package, level)
           ~~~~~~~~~~~~~~~~~~~~~~^^^^^^^^^^^^^^^^^^^^^^^^^^^^^^
  File "<frozen importlib._bootstrap>", line 1387, in _gcd_import
  File "<frozen importlib._bootstrap>", line 1360, in _find_and_load
  File "<frozen importlib._bootstrap>", line 1331, in _find_and_load_unlocked
  File "<frozen importlib._bootstrap>", line 935, in _load_unlocked
  File "<frozen importlib._bootstrap_external>", line 1026, in exec_module
  File "<frozen importlib._bootstrap>", line 488, in _call_with_frames_removed
  File "/usr/local/lib/python3.13/site-packages/tortoise/backends/asyncpg/__init__.py", line 1, in <module>
    from .client import AsyncpgDBClient
  File "/usr/local/lib/python3.13/site-packages/tortoise/backends/asyncpg/client.py", line 5, in <module>
    import asyncpg
ModuleNotFoundError: No module named 'asyncpg'

ERROR:    Application startup failed. Exiting.
INFO:     Started server process [1]
INFO:     Waiting for application startup.
ERROR:    Traceback (most recent call last):
  File "/usr/local/lib/python3.13/site-packages/tortoise/connection.py", line 122, in get
    return storage[conn_alias]
           ~~~~~~~^^^^^^^^^^^^
KeyError: 'default'

During handling of the above exception, another exception occurred:

Traceback (most recent call last):
  File "/usr/local/lib/python3.13/site-packages/starlette/routing.py", line 677, in lifespan
    async with self.lifespan_context(app) as maybe_state:
               ~~~~~~~~~~~~~~~~~~~~~^^^^^
  File "/usr/local/lib/python3.13/site-packages/starlette/routing.py", line 566, in __aenter__
    await self._router.startup()
  File "/usr/local/lib/python3.13/site-packages/starlette/routing.py", line 654, in startup
    await handler()
  File "/usr/local/lib/python3.13/site-packages/tortoise/contrib/fastapi/__init__.py", line 263, in init_orm
    await orm.init_orm()
  File "/usr/local/lib/python3.13/site-packages/tortoise/contrib/fastapi/__init__.py", line 138, in init_orm
    await Tortoise.init(
    ...<7 lines>...
    )
  File "/usr/local/lib/python3.13/site-packages/tortoise/__init__.py", line 512, in init
    await connections._init(connections_config, _create_db)
  File "/usr/local/lib/python3.13/site-packages/tortoise/connection.py", line 33, in _init
    await self._init_connections()
  File "/usr/local/lib/python3.13/site-packages/tortoise/connection.py", line 94, in _init_connections
    connection: "BaseDBAsyncClient" = self.get(alias)
                                      ~~~~~~~~^^^^^^^
  File "/usr/local/lib/python3.13/site-packages/tortoise/connection.py", line 124, in get
    connection: BaseDBAsyncClient = self._create_connection(conn_alias)
                                    ~~~~~~~~~~~~~~~~~~~~~~~^^^^^^^^^^^^
  File "/usr/local/lib/python3.13/site-packages/tortoise/connection.py", line 102, in _create_connection
    client_class = self._discover_client_class(db_info)
  File "/usr/local/lib/python3.13/site-packages/tortoise/connection.py", line 71, in _discover_client_class
    engine_module = importlib.import_module(engine_str)
  File "/usr/local/lib/python3.13/importlib/__init__.py", line 88, in import_module
    return _bootstrap._gcd_import(name[level:], package, level)
           ~~~~~~~~~~~~~~~~~~~~~~^^^^^^^^^^^^^^^^^^^^^^^^^^^^^^
  File "<frozen importlib._bootstrap>", line 1387, in _gcd_import
  File "<frozen importlib._bootstrap>", line 1360, in _find_and_load
  File "<frozen importlib._bootstrap>", line 1331, in _find_and_load_unlocked
  File "<frozen importlib._bootstrap>", line 935, in _load_unlocked
  File "<frozen importlib._bootstrap_external>", line 1026, in exec_module
  File "<frozen importlib._bootstrap>", line 488, in _call_with_frames_removed
  File "/usr/local/lib/python3.13/site-packages/tortoise/backends/asyncpg/__init__.py", line 1, in <module>
    from .client import AsyncpgDBClient
  File "/usr/local/lib/python3.13/site-packages/tortoise/backends/asyncpg/client.py", line 5, in <module>
    import asyncpg
ModuleNotFoundError: No module named 'asyncpg'

ERROR:    Application startup failed. Exiting.
INFO:     Started server process [1]
INFO:     Waiting for application startup.
ERROR:    Traceback (most recent call last):
  File "/usr/local/lib/python3.13/site-packages/tortoise/connection.py", line 122, in get
    return storage[conn_alias]
           ~~~~~~~^^^^^^^^^^^^
KeyError: 'default'

During handling of the above exception, another exception occurred:

Traceback (most recent call last):
  File "/usr/local/lib/python3.13/site-packages/starlette/routing.py", line 677, in lifespan
    async with self.lifespan_context(app) as maybe_state:
               ~~~~~~~~~~~~~~~~~~~~~^^^^^
  File "/usr/local/lib/python3.13/site-packages/starlette/routing.py", line 566, in __aenter__
    await self._router.startup()
  File "/usr/local/lib/python3.13/site-packages/starlette/routing.py", line 654, in startup
    await handler()
  File "/usr/local/lib/python3.13/site-packages/tortoise/contrib/fastapi/__init__.py", line 263, in init_orm
    await orm.init_orm()
  File "/usr/local/lib/python3.13/site-packages/tortoise/contrib/fastapi/__init__.py", line 138, in init_orm
    await Tortoise.init(
    ...<7 lines>...
    )
  File "/usr/local/lib/python3.13/site-packages/tortoise/__init__.py", line 512, in init
    await connections._init(connections_config, _create_db)
  File "/usr/local/lib/python3.13/site-packages/tortoise/connection.py", line 33, in _init
    await self._init_connections()
  File "/usr/local/lib/python3.13/site-packages/tortoise/connection.py", line 94, in _init_connections
    connection: "BaseDBAsyncClient" = self.get(alias)
                                      ~~~~~~~~^^^^^^^
  File "/usr/local/lib/python3.13/site-packages/tortoise/connection.py", line 124, in get
    connection: BaseDBAsyncClient = self._create_connection(conn_alias)
                                    ~~~~~~~~~~~~~~~~~~~~~~~^^^^^^^^^^^^
  File "/usr/local/lib/python3.13/site-packages/tortoise/connection.py", line 102, in _create_connection
    client_class = self._discover_client_class(db_info)
  File "/usr/local/lib/python3.13/site-packages/tortoise/connection.py", line 71, in _discover_client_class
    engine_module = importlib.import_module(engine_str)
  File "/usr/local/lib/python3.13/importlib/__init__.py", line 88, in import_module
    return _bootstrap._gcd_import(name[level:], package, level)
           ~~~~~~~~~~~~~~~~~~~~~~^^^^^^^^^^^^^^^^^^^^^^^^^^^^^^
  File "<frozen importlib._bootstrap>", line 1387, in _gcd_import
  File "<frozen importlib._bootstrap>", line 1360, in _find_and_load
  File "<frozen importlib._bootstrap>", line 1331, in _find_and_load_unlocked
  File "<frozen importlib._bootstrap>", line 935, in _load_unlocked
  File "<frozen importlib._bootstrap_external>", line 1026, in exec_module
  File "<frozen importlib._bootstrap>", line 488, in _call_with_frames_removed
  File "/usr/local/lib/python3.13/site-packages/tortoise/backends/asyncpg/__init__.py", line 1, in <module>
    from .client import AsyncpgDBClient
  File "/usr/local/lib/python3.13/site-packages/tortoise/backends/asyncpg/client.py", line 5, in <module>
    import asyncpg
ModuleNotFoundError: No module named 'asyncpg'

ERROR:    Application startup failed. Exiting.
INFO:     Started server process [1]
INFO:     Waiting for application startup.
ERROR:    Traceback (most recent call last):
  File "/usr/local/lib/python3.13/site-packages/tortoise/connection.py", line 122, in get
    return storage[conn_alias]
           ~~~~~~~^^^^^^^^^^^^
KeyError: 'default'

During handling of the above exception, another exception occurred:

Traceback (most recent call last):
  File "/usr/local/lib/python3.13/site-packages/starlette/routing.py", line 677, in lifespan
    async with self.lifespan_context(app) as maybe_state:
               ~~~~~~~~~~~~~~~~~~~~~^^^^^
  File "/usr/local/lib/python3.13/site-packages/starlette/routing.py", line 566, in __aenter__
    await self._router.startup()
  File "/usr/local/lib/python3.13/site-packages/starlette/routing.py", line 654, in startup
    await handler()
  File "/usr/local/lib/python3.13/site-packages/tortoise/contrib/fastapi/__init__.py", line 263, in init_orm
    await orm.init_orm()
  File "/usr/local/lib/python3.13/site-packages/tortoise/contrib/fastapi/__init__.py", line 138, in init_orm
    await Tortoise.init(
    ...<7 lines>...
    )
  File "/usr/local/lib/python3.13/site-packages/tortoise/__init__.py", line 512, in init
    await connections._init(connections_config, _create_db)
  File "/usr/local/lib/python3.13/site-packages/tortoise/connection.py", line 33, in _init
    await self._init_connections()
  File "/usr/local/lib/python3.13/site-packages/tortoise/connection.py", line 94, in _init_connections
    connection: "BaseDBAsyncClient" = self.get(alias)
                                      ~~~~~~~~^^^^^^^
  File "/usr/local/lib/python3.13/site-packages/tortoise/connection.py", line 124, in get
    connection: BaseDBAsyncClient = self._create_connection(conn_alias)
                                    ~~~~~~~~~~~~~~~~~~~~~~~^^^^^^^^^^^^
  File "/usr/local/lib/python3.13/site-packages/tortoise/connection.py", line 102, in _create_connection
    client_class = self._discover_client_class(db_info)
  File "/usr/local/lib/python3.13/site-packages/tortoise/connection.py", line 71, in _discover_client_class
    engine_module = importlib.import_module(engine_str)
  File "/usr/local/lib/python3.13/importlib/__init__.py", line 88, in import_module
    return _bootstrap._gcd_import(name[level:], package, level)
           ~~~~~~~~~~~~~~~~~~~~~~^^^^^^^^^^^^^^^^^^^^^^^^^^^^^^
  File "<frozen importlib._bootstrap>", line 1387, in _gcd_import
  File "<frozen importlib._bootstrap>", line 1360, in _find_and_load
  File "<frozen importlib._bootstrap>", line 1331, in _find_and_load_unlocked
  File "<frozen importlib._bootstrap>", line 935, in _load_unlocked
  File "<frozen importlib._bootstrap_external>", line 1026, in exec_module
  File "<frozen importlib._bootstrap>", line 488, in _call_with_frames_removed
  File "/usr/local/lib/python3.13/site-packages/tortoise/backends/asyncpg/__init__.py", line 1, in <module>
    from .client import AsyncpgDBClient
  File "/usr/local/lib/python3.13/site-packages/tortoise/backends/asyncpg/client.py", line 5, in <module>
    import asyncpg
ModuleNotFoundError: No module named 'asyncpg'

ERROR:    Application startup failed. Exiting.
INFO:     Started server process [1]
INFO:     Waiting for application startup.
ERROR:    Traceback (most recent call last):
  File "/usr/local/lib/python3.13/site-packages/tortoise/connection.py", line 122, in get
    return storage[conn_alias]
           ~~~~~~~^^^^^^^^^^^^
KeyError: 'default'

During handling of the above exception, another exception occurred:

Traceback (most recent call last):
  File "/usr/local/lib/python3.13/site-packages/starlette/routing.py", line 677, in lifespan
    async with self.lifespan_context(app) as maybe_state:
               ~~~~~~~~~~~~~~~~~~~~~^^^^^
  File "/usr/local/lib/python3.13/site-packages/starlette/routing.py", line 566, in __aenter__
    await self._router.startup()
  File "/usr/local/lib/python3.13/site-packages/starlette/routing.py", line 654, in startup
    await handler()
  File "/usr/local/lib/python3.13/site-packages/tortoise/contrib/fastapi/__init__.py", line 263, in init_orm
    await orm.init_orm()
  File "/usr/local/lib/python3.13/site-packages/tortoise/contrib/fastapi/__init__.py", line 138, in init_orm
    await Tortoise.init(
    ...<7 lines>...
    )
  File "/usr/local/lib/python3.13/site-packages/tortoise/__init__.py", line 512, in init
    await connections._init(connections_config, _create_db)
  File "/usr/local/lib/python3.13/site-packages/tortoise/connection.py", line 33, in _init
    await self._init_connections()
  File "/usr/local/lib/python3.13/site-packages/tortoise/connection.py", line 94, in _init_connections
    connection: "BaseDBAsyncClient" = self.get(alias)
                                      ~~~~~~~~^^^^^^^
  File "/usr/local/lib/python3.13/site-packages/tortoise/connection.py", line 124, in get
    connection: BaseDBAsyncClient = self._create_connection(conn_alias)
                                    ~~~~~~~~~~~~~~~~~~~~~~~^^^^^^^^^^^^
  File "/usr/local/lib/python3.13/site-packages/tortoise/connection.py", line 102, in _create_connection
    client_class = self._discover_client_class(db_info)
  File "/usr/local/lib/python3.13/site-packages/tortoise/connection.py", line 71, in _discover_client_class
    engine_module = importlib.import_module(engine_str)
  File "/usr/local/lib/python3.13/importlib/__init__.py", line 88, in import_module
    return _bootstrap._gcd_import(name[level:], package, level)
           ~~~~~~~~~~~~~~~~~~~~~~^^^^^^^^^^^^^^^^^^^^^^^^^^^^^^
  File "<frozen importlib._bootstrap>", line 1387, in _gcd_import
  File "<frozen importlib._bootstrap>", line 1360, in _find_and_load
  File "<frozen importlib._bootstrap>", line 1331, in _find_and_load_unlocked
  File "<frozen importlib._bootstrap>", line 935, in _load_unlocked
  File "<frozen importlib._bootstrap_external>", line 1026, in exec_module
  File "<frozen importlib._bootstrap>", line 488, in _call_with_frames_removed
  File "/usr/local/lib/python3.13/site-packages/tortoise/backends/asyncpg/__init__.py", line 1, in <module>
    from .client import AsyncpgDBClient
  File "/usr/local/lib/python3.13/site-packages/tortoise/backends/asyncpg/client.py", line 5, in <module>
    import asyncpg
ModuleNotFoundError: No module named 'asyncpg'

ERROR:    Application startup failed. Exiting.
INFO:     Started server process [1]
INFO:     Waiting for application startup.
ERROR:    Traceback (most recent call last):
  File "/usr/local/lib/python3.13/site-packages/tortoise/connection.py", line 122, in get
    return storage[conn_alias]
           ~~~~~~~^^^^^^^^^^^^
KeyError: 'default'

During handling of the above exception, another exception occurred:

Traceback (most recent call last):
  File "/usr/local/lib/python3.13/site-packages/starlette/routing.py", line 677, in lifespan
    async with self.lifespan_context(app) as maybe_state:
               ~~~~~~~~~~~~~~~~~~~~~^^^^^
  File "/usr/local/lib/python3.13/site-packages/starlette/routing.py", line 566, in __aenter__
    await self._router.startup()
  File "/usr/local/lib/python3.13/site-packages/starlette/routing.py", line 654, in startup
    await handler()
  File "/usr/local/lib/python3.13/site-packages/tortoise/contrib/fastapi/__init__.py", line 263, in init_orm
    await orm.init_orm()
  File "/usr/local/lib/python3.13/site-packages/tortoise/contrib/fastapi/__init__.py", line 138, in init_orm
    await Tortoise.init(
    ...<7 lines>...
    )
  File "/usr/local/lib/python3.13/site-packages/tortoise/__init__.py", line 512, in init
    await connections._init(connections_config, _create_db)
  File "/usr/local/lib/python3.13/site-packages/tortoise/connection.py", line 33, in _init
    await self._init_connections()
  File "/usr/local/lib/python3.13/site-packages/tortoise/connection.py", line 94, in _init_connections
    connection: "BaseDBAsyncClient" = self.get(alias)
                                      ~~~~~~~~^^^^^^^
  File "/usr/local/lib/python3.13/site-packages/tortoise/connection.py", line 124, in get
    connection: BaseDBAsyncClient = self._create_connection(conn_alias)
                                    ~~~~~~~~~~~~~~~~~~~~~~~^^^^^^^^^^^^
  File "/usr/local/lib/python3.13/site-packages/tortoise/connection.py", line 102, in _create_connection
    client_class = self._discover_client_class(db_info)
  File "/usr/local/lib/python3.13/site-packages/tortoise/connection.py", line 71, in _discover_client_class
    engine_module = importlib.import_module(engine_str)
  File "/usr/local/lib/python3.13/importlib/__init__.py", line 88, in import_module
    return _bootstrap._gcd_import(name[level:], package, level)
           ~~~~~~~~~~~~~~~~~~~~~~^^^^^^^^^^^^^^^^^^^^^^^^^^^^^^
  File "<frozen importlib._bootstrap>", line 1387, in _gcd_import
  File "<frozen importlib._bootstrap>", line 1360, in _find_and_load
  File "<frozen importlib._bootstrap>", line 1331, in _find_and_load_unlocked
  File "<frozen importlib._bootstrap>", line 935, in _load_unlocked
  File "<frozen importlib._bootstrap_external>", line 1026, in exec_module
  File "<frozen importlib._bootstrap>", line 488, in _call_with_frames_removed
  File "/usr/local/lib/python3.13/site-packages/tortoise/backends/asyncpg/__init__.py", line 1, in <module>
    from .client import AsyncpgDBClient
  File "/usr/local/lib/python3.13/site-packages/tortoise/backends/asyncpg/client.py", line 5, in <module>
    import asyncpg
ModuleNotFoundError: No module named 'asyncpg'

ERROR:    Application startup failed. Exiting.
INFO:     Started server process [1]
INFO:     Waiting for application startup.
ERROR:    Traceback (most recent call last):
  File "/usr/local/lib/python3.13/site-packages/tortoise/connection.py", line 122, in get
    return storage[conn_alias]
           ~~~~~~~^^^^^^^^^^^^
KeyError: 'default'

During handling of the above exception, another exception occurred:

Traceback (most recent call last):
  File "/usr/local/lib/python3.13/site-packages/starlette/routing.py", line 677, in lifespan
    async with self.lifespan_context(app) as maybe_state:
               ~~~~~~~~~~~~~~~~~~~~~^^^^^
  File "/usr/local/lib/python3.13/site-packages/starlette/routing.py", line 566, in __aenter__
    await self._router.startup()
  File "/usr/local/lib/python3.13/site-packages/starlette/routing.py", line 654, in startup
    await handler()
  File "/usr/local/lib/python3.13/site-packages/tortoise/contrib/fastapi/__init__.py", line 263, in init_orm
    await orm.init_orm()
  File "/usr/local/lib/python3.13/site-packages/tortoise/contrib/fastapi/__init__.py", line 138, in init_orm
    await Tortoise.init(
    ...<7 lines>...
    )
  File "/usr/local/lib/python3.13/site-packages/tortoise/__init__.py", line 512, in init
    await connections._init(connections_config, _create_db)
  File "/usr/local/lib/python3.13/site-packages/tortoise/connection.py", line 33, in _init
    await self._init_connections()
  File "/usr/local/lib/python3.13/site-packages/tortoise/connection.py", line 94, in _init_connections
    connection: "BaseDBAsyncClient" = self.get(alias)
                                      ~~~~~~~~^^^^^^^
  File "/usr/local/lib/python3.13/site-packages/tortoise/connection.py", line 124, in get
    connection: BaseDBAsyncClient = self._create_connection(conn_alias)
                                    ~~~~~~~~~~~~~~~~~~~~~~~^^^^^^^^^^^^
  File "/usr/local/lib/python3.13/site-packages/tortoise/connection.py", line 102, in _create_connection
    client_class = self._discover_client_class(db_info)
  File "/usr/local/lib/python3.13/site-packages/tortoise/connection.py", line 71, in _discover_client_class
    engine_module = importlib.import_module(engine_str)
  File "/usr/local/lib/python3.13/importlib/__init__.py", line 88, in import_module
    return _bootstrap._gcd_import(name[level:], package, level)
           ~~~~~~~~~~~~~~~~~~~~~~^^^^^^^^^^^^^^^^^^^^^^^^^^^^^^
  File "<frozen importlib._bootstrap>", line 1387, in _gcd_import
  File "<frozen importlib._bootstrap>", line 1360, in _find_and_load
  File "<frozen importlib._bootstrap>", line 1331, in _find_and_load_unlocked
  File "<frozen importlib._bootstrap>", line 935, in _load_unlocked
  File "<frozen importlib._bootstrap_external>", line 1026, in exec_module
  File "<frozen importlib._bootstrap>", line 488, in _call_with_frames_removed
  File "/usr/local/lib/python3.13/site-packages/tortoise/backends/asyncpg/__init__.py", line 1, in <module>
    from .client import AsyncpgDBClient
  File "/usr/local/lib/python3.13/site-packages/tortoise/backends/asyncpg/client.py", line 5, in <module>
    import asyncpg
ModuleNotFoundError: No module named 'asyncpg'

ERROR:    Application startup failed. Exiting.
INFO:     Started server process [1]
INFO:     Waiting for application startup.
ERROR:    Traceback (most recent call last):
  File "/usr/local/lib/python3.13/site-packages/tortoise/connection.py", line 122, in get
    return storage[conn_alias]
           ~~~~~~~^^^^^^^^^^^^
KeyError: 'default'

During handling of the above exception, another exception occurred:

Traceback (most recent call last):
  File "/usr/local/lib/python3.13/site-packages/starlette/routing.py", line 677, in lifespan
    async with self.lifespan_context(app) as maybe_state:
               ~~~~~~~~~~~~~~~~~~~~~^^^^^
  File "/usr/local/lib/python3.13/site-packages/starlette/routing.py", line 566, in __aenter__
    await self._router.startup()
  File "/usr/local/lib/python3.13/site-packages/starlette/routing.py", line 654, in startup
    await handler()
  File "/usr/local/lib/python3.13/site-packages/tortoise/contrib/fastapi/__init__.py", line 263, in init_orm
    await orm.init_orm()
  File "/usr/local/lib/python3.13/site-packages/tortoise/contrib/fastapi/__init__.py", line 138, in init_orm
    await Tortoise.init(
    ...<7 lines>...
    )
  File "/usr/local/lib/python3.13/site-packages/tortoise/__init__.py", line 512, in init
    await connections._init(connections_config, _create_db)
  File "/usr/local/lib/python3.13/site-packages/tortoise/connection.py", line 33, in _init
    await self._init_connections()
  File "/usr/local/lib/python3.13/site-packages/tortoise/connection.py", line 94, in _init_connections
    connection: "BaseDBAsyncClient" = self.get(alias)
                                      ~~~~~~~~^^^^^^^
  File "/usr/local/lib/python3.13/site-packages/tortoise/connection.py", line 124, in get
    connection: BaseDBAsyncClient = self._create_connection(conn_alias)
                                    ~~~~~~~~~~~~~~~~~~~~~~~^^^^^^^^^^^^
  File "/usr/local/lib/python3.13/site-packages/tortoise/connection.py", line 102, in _create_connection
    client_class = self._discover_client_class(db_info)
  File "/usr/local/lib/python3.13/site-packages/tortoise/connection.py", line 71, in _discover_client_class
    engine_module = importlib.import_module(engine_str)
  File "/usr/local/lib/python3.13/importlib/__init__.py", line 88, in import_module
    return _bootstrap._gcd_import(name[level:], package, level)
           ~~~~~~~~~~~~~~~~~~~~~~^^^^^^^^^^^^^^^^^^^^^^^^^^^^^^
  File "<frozen importlib._bootstrap>", line 1387, in _gcd_import
  File "<frozen importlib._bootstrap>", line 1360, in _find_and_load
  File "<frozen importlib._bootstrap>", line 1331, in _find_and_load_unlocked
  File "<frozen importlib._bootstrap>", line 935, in _load_unlocked
  File "<frozen importlib._bootstrap_external>", line 1026, in exec_module
  File "<frozen importlib._bootstrap>", line 488, in _call_with_frames_removed
  File "/usr/local/lib/python3.13/site-packages/tortoise/backends/asyncpg/__init__.py", line 1, in <module>
    from .client import AsyncpgDBClient
  File "/usr/local/lib/python3.13/site-packages/tortoise/backends/asyncpg/client.py", line 5, in <module>
    import asyncpg
ModuleNotFoundError: No module named 'asyncpg'

ERROR:    Application startup failed. Exiting.
INFO:     Started server process [1]
INFO:     Waiting for application startup.
ERROR:    Traceback (most recent call last):
  File "/usr/local/lib/python3.13/site-packages/tortoise/connection.py", line 122, in get
    return storage[conn_alias]
           ~~~~~~~^^^^^^^^^^^^
KeyError: 'default'

During handling of the above exception, another exception occurred:

Traceback (most recent call last):
  File "/usr/local/lib/python3.13/site-packages/starlette/routing.py", line 677, in lifespan
    async with self.lifespan_context(app) as maybe_state:
               ~~~~~~~~~~~~~~~~~~~~~^^^^^
  File "/usr/local/lib/python3.13/site-packages/starlette/routing.py", line 566, in __aenter__
    await self._router.startup()
  File "/usr/local/lib/python3.13/site-packages/starlette/routing.py", line 654, in startup
    await handler()
  File "/usr/local/lib/python3.13/site-packages/tortoise/contrib/fastapi/__init__.py", line 263, in init_orm
    await orm.init_orm()
  File "/usr/local/lib/python3.13/site-packages/tortoise/contrib/fastapi/__init__.py", line 138, in init_orm
    await Tortoise.init(
    ...<7 lines>...
    )
  File "/usr/local/lib/python3.13/site-packages/tortoise/__init__.py", line 512, in init
    await connections._init(connections_config, _create_db)
  File "/usr/local/lib/python3.13/site-packages/tortoise/connection.py", line 33, in _init
    await self._init_connections()
  File "/usr/local/lib/python3.13/site-packages/tortoise/connection.py", line 94, in _init_connections
    connection: "BaseDBAsyncClient" = self.get(alias)
                                      ~~~~~~~~^^^^^^^
  File "/usr/local/lib/python3.13/site-packages/tortoise/connection.py", line 124, in get
    connection: BaseDBAsyncClient = self._create_connection(conn_alias)
                                    ~~~~~~~~~~~~~~~~~~~~~~~^^^^^^^^^^^^
  File "/usr/local/lib/python3.13/site-packages/tortoise/connection.py", line 102, in _create_connection
    client_class = self._discover_client_class(db_info)
  File "/usr/local/lib/python3.13/site-packages/tortoise/connection.py", line 71, in _discover_client_class
    engine_module = importlib.import_module(engine_str)
  File "/usr/local/lib/python3.13/importlib/__init__.py", line 88, in import_module
    return _bootstrap._gcd_import(name[level:], package, level)
           ~~~~~~~~~~~~~~~~~~~~~~^^^^^^^^^^^^^^^^^^^^^^^^^^^^^^
  File "<frozen importlib._bootstrap>", line 1387, in _gcd_import
  File "<frozen importlib._bootstrap>", line 1360, in _find_and_load
  File "<frozen importlib._bootstrap>", line 1331, in _find_and_load_unlocked
  File "<frozen importlib._bootstrap>", line 935, in _load_unlocked
  File "<frozen importlib._bootstrap_external>", line 1026, in exec_module
  File "<frozen importlib._bootstrap>", line 488, in _call_with_frames_removed
  File "/usr/local/lib/python3.13/site-packages/tortoise/backends/asyncpg/__init__.py", line 1, in <module>
    from .client import AsyncpgDBClient
  File "/usr/local/lib/python3.13/site-packages/tortoise/backends/asyncpg/client.py", line 5, in <module>
    import asyncpg
ModuleNotFoundError: No module named 'asyncpg'

ERROR:    Application startup failed. Exiting.
INFO:     Started server process [1]
INFO:     Waiting for application startup.
ERROR:    Traceback (most recent call last):
  File "/usr/local/lib/python3.13/site-packages/tortoise/connection.py", line 122, in get
    return storage[conn_alias]
           ~~~~~~~^^^^^^^^^^^^
KeyError: 'default'

During handling of the above exception, another exception occurred:

Traceback (most recent call last):
  File "/usr/local/lib/python3.13/site-packages/starlette/routing.py", line 677, in lifespan
    async with self.lifespan_context(app) as maybe_state:
               ~~~~~~~~~~~~~~~~~~~~~^^^^^
  File "/usr/local/lib/python3.13/site-packages/starlette/routing.py", line 566, in __aenter__
    await self._router.startup()
  File "/usr/local/lib/python3.13/site-packages/starlette/routing.py", line 654, in startup
    await handler()
  File "/usr/local/lib/python3.13/site-packages/tortoise/contrib/fastapi/__init__.py", line 263, in init_orm
    await orm.init_orm()
  File "/usr/local/lib/python3.13/site-packages/tortoise/contrib/fastapi/__init__.py", line 138, in init_orm
    await Tortoise.init(
    ...<7 lines>...
    )
  File "/usr/local/lib/python3.13/site-packages/tortoise/__init__.py", line 512, in init
    await connections._init(connections_config, _create_db)
  File "/usr/local/lib/python3.13/site-packages/tortoise/connection.py", line 33, in _init
    await self._init_connections()
  File "/usr/local/lib/python3.13/site-packages/tortoise/connection.py", line 94, in _init_connections
    connection: "BaseDBAsyncClient" = self.get(alias)
                                      ~~~~~~~~^^^^^^^
  File "/usr/local/lib/python3.13/site-packages/tortoise/connection.py", line 124, in get
    connection: BaseDBAsyncClient = self._create_connection(conn_alias)
                                    ~~~~~~~~~~~~~~~~~~~~~~~^^^^^^^^^^^^
  File "/usr/local/lib/python3.13/site-packages/tortoise/connection.py", line 102, in _create_connection
    client_class = self._discover_client_class(db_info)
  File "/usr/local/lib/python3.13/site-packages/tortoise/connection.py", line 71, in _discover_client_class
    engine_module = importlib.import_module(engine_str)
  File "/usr/local/lib/python3.13/importlib/__init__.py", line 88, in import_module
    return _bootstrap._gcd_import(name[level:], package, level)
           ~~~~~~~~~~~~~~~~~~~~~~^^^^^^^^^^^^^^^^^^^^^^^^^^^^^^
  File "<frozen importlib._bootstrap>", line 1387, in _gcd_import
  File "<frozen importlib._bootstrap>", line 1360, in _find_and_load
  File "<frozen importlib._bootstrap>", line 1331, in _find_and_load_unlocked
  File "<frozen importlib._bootstrap>", line 935, in _load_unlocked
  File "<frozen importlib._bootstrap_external>", line 1026, in exec_module
  File "<frozen importlib._bootstrap>", line 488, in _call_with_frames_removed
  File "/usr/local/lib/python3.13/site-packages/tortoise/backends/asyncpg/__init__.py", line 1, in <module>
    from .client import AsyncpgDBClient
  File "/usr/local/lib/python3.13/site-packages/tortoise/backends/asyncpg/client.py", line 5, in <module>
    import asyncpg
ModuleNotFoundError: No module named 'asyncpg'

ERROR:    Application startup failed. Exiting.
INFO:     Started server process [1]
INFO:     Waiting for application startup.
ERROR:    Traceback (most recent call last):
  File "/usr/local/lib/python3.13/site-packages/tortoise/connection.py", line 122, in get
    return storage[conn_alias]
           ~~~~~~~^^^^^^^^^^^^
KeyError: 'default'

During handling of the above exception, another exception occurred:

Traceback (most recent call last):
  File "/usr/local/lib/python3.13/site-packages/starlette/routing.py", line 677, in lifespan
    async with self.lifespan_context(app) as maybe_state:
               ~~~~~~~~~~~~~~~~~~~~~^^^^^
  File "/usr/local/lib/python3.13/site-packages/starlette/routing.py", line 566, in __aenter__
    await self._router.startup()
  File "/usr/local/lib/python3.13/site-packages/starlette/routing.py", line 654, in startup
    await handler()
  File "/usr/local/lib/python3.13/site-packages/tortoise/contrib/fastapi/__init__.py", line 263, in init_orm
    await orm.init_orm()
  File "/usr/local/lib/python3.13/site-packages/tortoise/contrib/fastapi/__init__.py", line 138, in init_orm
    await Tortoise.init(
    ...<7 lines>...
    )
  File "/usr/local/lib/python3.13/site-packages/tortoise/__init__.py", line 512, in init
    await connections._init(connections_config, _create_db)
  File "/usr/local/lib/python3.13/site-packages/tortoise/connection.py", line 33, in _init
    await self._init_connections()
  File "/usr/local/lib/python3.13/site-packages/tortoise/connection.py", line 94, in _init_connections
    connection: "BaseDBAsyncClient" = self.get(alias)
                                      ~~~~~~~~^^^^^^^
  File "/usr/local/lib/python3.13/site-packages/tortoise/connection.py", line 124, in get
    connection: BaseDBAsyncClient = self._create_connection(conn_alias)
                                    ~~~~~~~~~~~~~~~~~~~~~~~^^^^^^^^^^^^
  File "/usr/local/lib/python3.13/site-packages/tortoise/connection.py", line 102, in _create_connection
    client_class = self._discover_client_class(db_info)
  File "/usr/local/lib/python3.13/site-packages/tortoise/connection.py", line 71, in _discover_client_class
    engine_module = importlib.import_module(engine_str)
  File "/usr/local/lib/python3.13/importlib/__init__.py", line 88, in import_module
    return _bootstrap._gcd_import(name[level:], package, level)
           ~~~~~~~~~~~~~~~~~~~~~~^^^^^^^^^^^^^^^^^^^^^^^^^^^^^^
  File "<frozen importlib._bootstrap>", line 1387, in _gcd_import
  File "<frozen importlib._bootstrap>", line 1360, in _find_and_load
  File "<frozen importlib._bootstrap>", line 1331, in _find_and_load_unlocked
  File "<frozen importlib._bootstrap>", line 935, in _load_unlocked
  File "<frozen importlib._bootstrap_external>", line 1026, in exec_module
  File "<frozen importlib._bootstrap>", line 488, in _call_with_frames_removed
  File "/usr/local/lib/python3.13/site-packages/tortoise/backends/asyncpg/__init__.py", line 1, in <module>
    from .client import AsyncpgDBClient
  File "/usr/local/lib/python3.13/site-packages/tortoise/backends/asyncpg/client.py", line 5, in <module>
    import asyncpg
ModuleNotFoundError: No module named 'asyncpg'

ERROR:    Application startup failed. Exiting.
INFO:     Started server process [1]
INFO:     Waiting for application startup.
ERROR:    Traceback (most recent call last):
  File "/usr/local/lib/python3.13/site-packages/tortoise/connection.py", line 122, in get
    return storage[conn_alias]
           ~~~~~~~^^^^^^^^^^^^
KeyError: 'default'

During handling of the above exception, another exception occurred:

Traceback (most recent call last):
  File "/usr/local/lib/python3.13/site-packages/starlette/routing.py", line 677, in lifespan
    async with self.lifespan_context(app) as maybe_state:
               ~~~~~~~~~~~~~~~~~~~~~^^^^^
  File "/usr/local/lib/python3.13/site-packages/starlette/routing.py", line 566, in __aenter__
    await self._router.startup()
  File "/usr/local/lib/python3.13/site-packages/starlette/routing.py", line 654, in startup
    await handler()
  File "/usr/local/lib/python3.13/site-packages/tortoise/contrib/fastapi/__init__.py", line 263, in init_orm
    await orm.init_orm()
  File "/usr/local/lib/python3.13/site-packages/tortoise/contrib/fastapi/__init__.py", line 138, in init_orm
    await Tortoise.init(
    ...<7 lines>...
    )
  File "/usr/local/lib/python3.13/site-packages/tortoise/__init__.py", line 512, in init
    await connections._init(connections_config, _create_db)
  File "/usr/local/lib/python3.13/site-packages/tortoise/connection.py", line 33, in _init
    await self._init_connections()
  File "/usr/local/lib/python3.13/site-packages/tortoise/connection.py", line 94, in _init_connections
    connection: "BaseDBAsyncClient" = self.get(alias)
                                      ~~~~~~~~^^^^^^^
  File "/usr/local/lib/python3.13/site-packages/tortoise/connection.py", line 124, in get
    connection: BaseDBAsyncClient = self._create_connection(conn_alias)
                                    ~~~~~~~~~~~~~~~~~~~~~~~^^^^^^^^^^^^
  File "/usr/local/lib/python3.13/site-packages/tortoise/connection.py", line 102, in _create_connection
    client_class = self._discover_client_class(db_info)
  File "/usr/local/lib/python3.13/site-packages/tortoise/connection.py", line 71, in _discover_client_class
    engine_module = importlib.import_module(engine_str)
  File "/usr/local/lib/python3.13/importlib/__init__.py", line 88, in import_module
    return _bootstrap._gcd_import(name[level:], package, level)
           ~~~~~~~~~~~~~~~~~~~~~~^^^^^^^^^^^^^^^^^^^^^^^^^^^^^^
  File "<frozen importlib._bootstrap>", line 1387, in _gcd_import
  File "<frozen importlib._bootstrap>", line 1360, in _find_and_load
  File "<frozen importlib._bootstrap>", line 1331, in _find_and_load_unlocked
  File "<frozen importlib._bootstrap>", line 935, in _load_unlocked
  File "<frozen importlib._bootstrap_external>", line 1026, in exec_module
  File "<frozen importlib._bootstrap>", line 488, in _call_with_frames_removed
  File "/usr/local/lib/python3.13/site-packages/tortoise/backends/asyncpg/__init__.py", line 1, in <module>
    from .client import AsyncpgDBClient
  File "/usr/local/lib/python3.13/site-packages/tortoise/backends/asyncpg/client.py", line 5, in <module>
    import asyncpg
ModuleNotFoundError: No module named 'asyncpg'

ERROR:    Application startup failed. Exiting.
INFO:     Started server process [1]
INFO:     Waiting for application startup.
ERROR:    Traceback (most recent call last):
  File "/usr/local/lib/python3.13/site-packages/tortoise/connection.py", line 122, in get
    return storage[conn_alias]
           ~~~~~~~^^^^^^^^^^^^
KeyError: 'default'

During handling of the above exception, another exception occurred:

Traceback (most recent call last):
  File "/usr/local/lib/python3.13/site-packages/starlette/routing.py", line 677, in lifespan
    async with self.lifespan_context(app) as maybe_state:
               ~~~~~~~~~~~~~~~~~~~~~^^^^^
  File "/usr/local/lib/python3.13/site-packages/starlette/routing.py", line 566, in __aenter__
    await self._router.startup()
  File "/usr/local/lib/python3.13/site-packages/starlette/routing.py", line 654, in startup
    await handler()
  File "/usr/local/lib/python3.13/site-packages/tortoise/contrib/fastapi/__init__.py", line 263, in init_orm
    await orm.init_orm()
  File "/usr/local/lib/python3.13/site-packages/tortoise/contrib/fastapi/__init__.py", line 138, in init_orm
    await Tortoise.init(
    ...<7 lines>...
    )
  File "/usr/local/lib/python3.13/site-packages/tortoise/__init__.py", line 512, in init
    await connections._init(connections_config, _create_db)
  File "/usr/local/lib/python3.13/site-packages/tortoise/connection.py", line 33, in _init
    await self._init_connections()
  File "/usr/local/lib/python3.13/site-packages/tortoise/connection.py", line 94, in _init_connections
    connection: "BaseDBAsyncClient" = self.get(alias)
                                      ~~~~~~~~^^^^^^^
  File "/usr/local/lib/python3.13/site-packages/tortoise/connection.py", line 124, in get
    connection: BaseDBAsyncClient = self._create_connection(conn_alias)
                                    ~~~~~~~~~~~~~~~~~~~~~~~^^^^^^^^^^^^
  File "/usr/local/lib/python3.13/site-packages/tortoise/connection.py", line 102, in _create_connection
    client_class = self._discover_client_class(db_info)
  File "/usr/local/lib/python3.13/site-packages/tortoise/connection.py", line 71, in _discover_client_class
    engine_module = importlib.import_module(engine_str)
  File "/usr/local/lib/python3.13/importlib/__init__.py", line 88, in import_module
    return _bootstrap._gcd_import(name[level:], package, level)
           ~~~~~~~~~~~~~~~~~~~~~~^^^^^^^^^^^^^^^^^^^^^^^^^^^^^^
  File "<frozen importlib._bootstrap>", line 1387, in _gcd_import
  File "<frozen importlib._bootstrap>", line 1360, in _find_and_load
  File "<frozen importlib._bootstrap>", line 1331, in _find_and_load_unlocked
  File "<frozen importlib._bootstrap>", line 935, in _load_unlocked
  File "<frozen importlib._bootstrap_external>", line 1026, in exec_module
  File "<frozen importlib._bootstrap>", line 488, in _call_with_frames_removed
  File "/usr/local/lib/python3.13/site-packages/tortoise/backends/asyncpg/__init__.py", line 1, in <module>
    from .client import AsyncpgDBClient
  File "/usr/local/lib/python3.13/site-packages/tortoise/backends/asyncpg/client.py", line 5, in <module>
    import asyncpg
ModuleNotFoundError: No module named 'asyncpg'

ERROR:    Application startup failed. Exiting.
INFO:     Started server process [1]
INFO:     Waiting for application startup.
ERROR:    Traceback (most recent call last):
  File "/usr/local/lib/python3.13/site-packages/tortoise/connection.py", line 122, in get
    return storage[conn_alias]
           ~~~~~~~^^^^^^^^^^^^
KeyError: 'default'

During handling of the above exception, another exception occurred:

Traceback (most recent call last):
  File "/usr/local/lib/python3.13/site-packages/starlette/routing.py", line 677, in lifespan
    async with self.lifespan_context(app) as maybe_state:
               ~~~~~~~~~~~~~~~~~~~~~^^^^^
  File "/usr/local/lib/python3.13/site-packages/starlette/routing.py", line 566, in __aenter__
    await self._router.startup()
  File "/usr/local/lib/python3.13/site-packages/starlette/routing.py", line 654, in startup
    await handler()
  File "/usr/local/lib/python3.13/site-packages/tortoise/contrib/fastapi/__init__.py", line 263, in init_orm
    await orm.init_orm()
  File "/usr/local/lib/python3.13/site-packages/tortoise/contrib/fastapi/__init__.py", line 138, in init_orm
    await Tortoise.init(
    ...<7 lines>...
    )
  File "/usr/local/lib/python3.13/site-packages/tortoise/__init__.py", line 512, in init
    await connections._init(connections_config, _create_db)
  File "/usr/local/lib/python3.13/site-packages/tortoise/connection.py", line 33, in _init
    await self._init_connections()
  File "/usr/local/lib/python3.13/site-packages/tortoise/connection.py", line 94, in _init_connections
    connection: "BaseDBAsyncClient" = self.get(alias)
                                      ~~~~~~~~^^^^^^^
  File "/usr/local/lib/python3.13/site-packages/tortoise/connection.py", line 124, in get
    connection: BaseDBAsyncClient = self._create_connection(conn_alias)
                                    ~~~~~~~~~~~~~~~~~~~~~~~^^^^^^^^^^^^
  File "/usr/local/lib/python3.13/site-packages/tortoise/connection.py", line 102, in _create_connection
    client_class = self._discover_client_class(db_info)
  File "/usr/local/lib/python3.13/site-packages/tortoise/connection.py", line 71, in _discover_client_class
    engine_module = importlib.import_module(engine_str)
  File "/usr/local/lib/python3.13/importlib/__init__.py", line 88, in import_module
    return _bootstrap._gcd_import(name[level:], package, level)
           ~~~~~~~~~~~~~~~~~~~~~~^^^^^^^^^^^^^^^^^^^^^^^^^^^^^^
  File "<frozen importlib._bootstrap>", line 1387, in _gcd_import
  File "<frozen importlib._bootstrap>", line 1360, in _find_and_load
  File "<frozen importlib._bootstrap>", line 1331, in _find_and_load_unlocked
  File "<frozen importlib._bootstrap>", line 935, in _load_unlocked
  File "<frozen importlib._bootstrap_external>", line 1026, in exec_module
  File "<frozen importlib._bootstrap>", line 488, in _call_with_frames_removed
  File "/usr/local/lib/python3.13/site-packages/tortoise/backends/asyncpg/__init__.py", line 1, in <module>
    from .client import AsyncpgDBClient
  File "/usr/local/lib/python3.13/site-packages/tortoise/backends/asyncpg/client.py", line 5, in <module>
    import asyncpg
ModuleNotFoundError: No module named 'asyncpg'

ERROR:    Application startup failed. Exiting.
INFO:     Started server process [1]
INFO:     Waiting for application startup.
ERROR:    Traceback (most recent call last):
  File "/usr/local/lib/python3.13/site-packages/tortoise/connection.py", line 122, in get
    return storage[conn_alias]
           ~~~~~~~^^^^^^^^^^^^
KeyError: 'default'

During handling of the above exception, another exception occurred:

Traceback (most recent call last):
  File "/usr/local/lib/python3.13/site-packages/starlette/routing.py", line 677, in lifespan
    async with self.lifespan_context(app) as maybe_state:
               ~~~~~~~~~~~~~~~~~~~~~^^^^^
  File "/usr/local/lib/python3.13/site-packages/starlette/routing.py", line 566, in __aenter__
    await self._router.startup()
  File "/usr/local/lib/python3.13/site-packages/starlette/routing.py", line 654, in startup
    await handler()
  File "/usr/local/lib/python3.13/site-packages/tortoise/contrib/fastapi/__init__.py", line 263, in init_orm
    await orm.init_orm()
  File "/usr/local/lib/python3.13/site-packages/tortoise/contrib/fastapi/__init__.py", line 138, in init_orm
    await Tortoise.init(
    ...<7 lines>...
    )
  File "/usr/local/lib/python3.13/site-packages/tortoise/__init__.py", line 512, in init
    await connections._init(connections_config, _create_db)
  File "/usr/local/lib/python3.13/site-packages/tortoise/connection.py", line 33, in _init
    await self._init_connections()
  File "/usr/local/lib/python3.13/site-packages/tortoise/connection.py", line 94, in _init_connections
    connection: "BaseDBAsyncClient" = self.get(alias)
                                      ~~~~~~~~^^^^^^^
  File "/usr/local/lib/python3.13/site-packages/tortoise/connection.py", line 124, in get
    connection: BaseDBAsyncClient = self._create_connection(conn_alias)
                                    ~~~~~~~~~~~~~~~~~~~~~~~^^^^^^^^^^^^
  File "/usr/local/lib/python3.13/site-packages/tortoise/connection.py", line 102, in _create_connection
    client_class = self._discover_client_class(db_info)
  File "/usr/local/lib/python3.13/site-packages/tortoise/connection.py", line 71, in _discover_client_class
    engine_module = importlib.import_module(engine_str)
  File "/usr/local/lib/python3.13/importlib/__init__.py", line 88, in import_module
    return _bootstrap._gcd_import(name[level:], package, level)
           ~~~~~~~~~~~~~~~~~~~~~~^^^^^^^^^^^^^^^^^^^^^^^^^^^^^^
  File "<frozen importlib._bootstrap>", line 1387, in _gcd_import
  File "<frozen importlib._bootstrap>", line 1360, in _find_and_load
  File "<frozen importlib._bootstrap>", line 1331, in _find_and_load_unlocked
  File "<frozen importlib._bootstrap>", line 935, in _load_unlocked
  File "<frozen importlib._bootstrap_external>", line 1026, in exec_module
  File "<frozen importlib._bootstrap>", line 488, in _call_with_frames_removed
  File "/usr/local/lib/python3.13/site-packages/tortoise/backends/asyncpg/__init__.py", line 1, in <module>
    from .client import AsyncpgDBClient
  File "/usr/local/lib/python3.13/site-packages/tortoise/backends/asyncpg/client.py", line 5, in <module>
    import asyncpg
ModuleNotFoundError: No module named 'asyncpg'

ERROR:    Application startup failed. Exiting.
INFO:     Started server process [1]
INFO:     Waiting for application startup.
ERROR:    Traceback (most recent call last):
  File "/usr/local/lib/python3.13/site-packages/tortoise/connection.py", line 122, in get
    return storage[conn_alias]
           ~~~~~~~^^^^^^^^^^^^
KeyError: 'default'

During handling of the above exception, another exception occurred:

Traceback (most recent call last):
  File "/usr/local/lib/python3.13/site-packages/starlette/routing.py", line 677, in lifespan
    async with self.lifespan_context(app) as maybe_state:
               ~~~~~~~~~~~~~~~~~~~~~^^^^^
  File "/usr/local/lib/python3.13/site-packages/starlette/routing.py", line 566, in __aenter__
    await self._router.startup()
  File "/usr/local/lib/python3.13/site-packages/starlette/routing.py", line 654, in startup
    await handler()
  File "/usr/local/lib/python3.13/site-packages/tortoise/contrib/fastapi/__init__.py", line 263, in init_orm
    await orm.init_orm()
  File "/usr/local/lib/python3.13/site-packages/tortoise/contrib/fastapi/__init__.py", line 138, in init_orm
    await Tortoise.init(
    ...<7 lines>...
    )
  File "/usr/local/lib/python3.13/site-packages/tortoise/__init__.py", line 512, in init
    await connections._init(connections_config, _create_db)
  File "/usr/local/lib/python3.13/site-packages/tortoise/connection.py", line 33, in _init
    await self._init_connections()
  File "/usr/local/lib/python3.13/site-packages/tortoise/connection.py", line 94, in _init_connections
    connection: "BaseDBAsyncClient" = self.get(alias)
                                      ~~~~~~~~^^^^^^^
  File "/usr/local/lib/python3.13/site-packages/tortoise/connection.py", line 124, in get
    connection: BaseDBAsyncClient = self._create_connection(conn_alias)
                                    ~~~~~~~~~~~~~~~~~~~~~~~^^^^^^^^^^^^
  File "/usr/local/lib/python3.13/site-packages/tortoise/connection.py", line 102, in _create_connection
    client_class = self._discover_client_class(db_info)
  File "/usr/local/lib/python3.13/site-packages/tortoise/connection.py", line 71, in _discover_client_class
    engine_module = importlib.import_module(engine_str)
  File "/usr/local/lib/python3.13/importlib/__init__.py", line 88, in import_module
    return _bootstrap._gcd_import(name[level:], package, level)
           ~~~~~~~~~~~~~~~~~~~~~~^^^^^^^^^^^^^^^^^^^^^^^^^^^^^^
  File "<frozen importlib._bootstrap>", line 1387, in _gcd_import
  File "<frozen importlib._bootstrap>", line 1360, in _find_and_load
  File "<frozen importlib._bootstrap>", line 1331, in _find_and_load_unlocked
  File "<frozen importlib._bootstrap>", line 935, in _load_unlocked
  File "<frozen importlib._bootstrap_external>", line 1026, in exec_module
  File "<frozen importlib._bootstrap>", line 488, in _call_with_frames_removed
  File "/usr/local/lib/python3.13/site-packages/tortoise/backends/asyncpg/__init__.py", line 1, in <module>
    from .client import AsyncpgDBClient
  File "/usr/local/lib/python3.13/site-packages/tortoise/backends/asyncpg/client.py", line 5, in <module>
    import asyncpg
ModuleNotFoundError: No module named 'asyncpg'

ERROR:    Application startup failed. Exiting.
INFO:     Started server process [1]
INFO:     Waiting for application startup.
ERROR:    Traceback (most recent call last):
  File "/usr/local/lib/python3.13/site-packages/tortoise/connection.py", line 122, in get
    return storage[conn_alias]
           ~~~~~~~^^^^^^^^^^^^
KeyError: 'default'

During handling of the above exception, another exception occurred:

Traceback (most recent call last):
  File "/usr/local/lib/python3.13/site-packages/starlette/routing.py", line 677, in lifespan
    async with self.lifespan_context(app) as maybe_state:
               ~~~~~~~~~~~~~~~~~~~~~^^^^^
  File "/usr/local/lib/python3.13/site-packages/starlette/routing.py", line 566, in __aenter__
    await self._router.startup()
  File "/usr/local/lib/python3.13/site-packages/starlette/routing.py", line 654, in startup
    await handler()
  File "/usr/local/lib/python3.13/site-packages/tortoise/contrib/fastapi/__init__.py", line 263, in init_orm
    await orm.init_orm()
  File "/usr/local/lib/python3.13/site-packages/tortoise/contrib/fastapi/__init__.py", line 138, in init_orm
    await Tortoise.init(
    ...<7 lines>...
    )
  File "/usr/local/lib/python3.13/site-packages/tortoise/__init__.py", line 512, in init
    await connections._init(connections_config, _create_db)
  File "/usr/local/lib/python3.13/site-packages/tortoise/connection.py", line 33, in _init
    await self._init_connections()
  File "/usr/local/lib/python3.13/site-packages/tortoise/connection.py", line 94, in _init_connections
    connection: "BaseDBAsyncClient" = self.get(alias)
                                      ~~~~~~~~^^^^^^^
  File "/usr/local/lib/python3.13/site-packages/tortoise/connection.py", line 124, in get
    connection: BaseDBAsyncClient = self._create_connection(conn_alias)
                                    ~~~~~~~~~~~~~~~~~~~~~~~^^^^^^^^^^^^
  File "/usr/local/lib/python3.13/site-packages/tortoise/connection.py", line 102, in _create_connection
    client_class = self._discover_client_class(db_info)
  File "/usr/local/lib/python3.13/site-packages/tortoise/connection.py", line 71, in _discover_client_class
    engine_module = importlib.import_module(engine_str)
  File "/usr/local/lib/python3.13/importlib/__init__.py", line 88, in import_module
    return _bootstrap._gcd_import(name[level:], package, level)
           ~~~~~~~~~~~~~~~~~~~~~~^^^^^^^^^^^^^^^^^^^^^^^^^^^^^^
  File "<frozen importlib._bootstrap>", line 1387, in _gcd_import
  File "<frozen importlib._bootstrap>", line 1360, in _find_and_load
  File "<frozen importlib._bootstrap>", line 1331, in _find_and_load_unlocked
  File "<frozen importlib._bootstrap>", line 935, in _load_unlocked
  File "<frozen importlib._bootstrap_external>", line 1026, in exec_module
  File "<frozen importlib._bootstrap>", line 488, in _call_with_frames_removed
  File "/usr/local/lib/python3.13/site-packages/tortoise/backends/asyncpg/__init__.py", line 1, in <module>
    from .client import AsyncpgDBClient
  File "/usr/local/lib/python3.13/site-packages/tortoise/backends/asyncpg/client.py", line 5, in <module>
    import asyncpg
ModuleNotFoundError: No module named 'asyncpg'

ERROR:    Application startup failed. Exiting.
INFO:     Started server process [1]
INFO:     Waiting for application startup.
ERROR:    Traceback (most recent call last):
  File "/usr/local/lib/python3.13/site-packages/tortoise/connection.py", line 122, in get
    return storage[conn_alias]
           ~~~~~~~^^^^^^^^^^^^
KeyError: 'default'

During handling of the above exception, another exception occurred:

Traceback (most recent call last):
  File "/usr/local/lib/python3.13/site-packages/starlette/routing.py", line 677, in lifespan
    async with self.lifespan_context(app) as maybe_state:
               ~~~~~~~~~~~~~~~~~~~~~^^^^^
  File "/usr/local/lib/python3.13/site-packages/starlette/routing.py", line 566, in __aenter__
    await self._router.startup()
  File "/usr/local/lib/python3.13/site-packages/starlette/routing.py", line 654, in startup
    await handler()
  File "/usr/local/lib/python3.13/site-packages/tortoise/contrib/fastapi/__init__.py", line 263, in init_orm
    await orm.init_orm()
  File "/usr/local/lib/python3.13/site-packages/tortoise/contrib/fastapi/__init__.py", line 138, in init_orm
    await Tortoise.init(
    ...<7 lines>...
    )
  File "/usr/local/lib/python3.13/site-packages/tortoise/__init__.py", line 512, in init
    await connections._init(connections_config, _create_db)
  File "/usr/local/lib/python3.13/site-packages/tortoise/connection.py", line 33, in _init
    await self._init_connections()
  File "/usr/local/lib/python3.13/site-packages/tortoise/connection.py", line 94, in _init_connections
    connection: "BaseDBAsyncClient" = self.get(alias)
                                      ~~~~~~~~^^^^^^^
  File "/usr/local/lib/python3.13/site-packages/tortoise/connection.py", line 124, in get
    connection: BaseDBAsyncClient = self._create_connection(conn_alias)
                                    ~~~~~~~~~~~~~~~~~~~~~~~^^^^^^^^^^^^
  File "/usr/local/lib/python3.13/site-packages/tortoise/connection.py", line 102, in _create_connection
    client_class = self._discover_client_class(db_info)
  File "/usr/local/lib/python3.13/site-packages/tortoise/connection.py", line 71, in _discover_client_class
    engine_module = importlib.import_module(engine_str)
  File "/usr/local/lib/python3.13/importlib/__init__.py", line 88, in import_module
    return _bootstrap._gcd_import(name[level:], package, level)
           ~~~~~~~~~~~~~~~~~~~~~~^^^^^^^^^^^^^^^^^^^^^^^^^^^^^^
  File "<frozen importlib._bootstrap>", line 1387, in _gcd_import
  File "<frozen importlib._bootstrap>", line 1360, in _find_and_load
  File "<frozen importlib._bootstrap>", line 1331, in _find_and_load_unlocked
  File "<frozen importlib._bootstrap>", line 935, in _load_unlocked
  File "<frozen importlib._bootstrap_external>", line 1026, in exec_module
  File "<frozen importlib._bootstrap>", line 488, in _call_with_frames_removed
  File "/usr/local/lib/python3.13/site-packages/tortoise/backends/asyncpg/__init__.py", line 1, in <module>
    from .client import AsyncpgDBClient
  File "/usr/local/lib/python3.13/site-packages/tortoise/backends/asyncpg/client.py", line 5, in <module>
    import asyncpg
ModuleNotFoundError: No module named 'asyncpg'

ERROR:    Application startup failed. Exiting.
INFO:     Started server process [1]
INFO:     Waiting for application startup.
ERROR:    Traceback (most recent call last):
  File "/usr/local/lib/python3.13/site-packages/tortoise/connection.py", line 122, in get
    return storage[conn_alias]
           ~~~~~~~^^^^^^^^^^^^
KeyError: 'default'

During handling of the above exception, another exception occurred:

Traceback (most recent call last):
  File "/usr/local/lib/python3.13/site-packages/starlette/routing.py", line 677, in lifespan
    async with self.lifespan_context(app) as maybe_state:
               ~~~~~~~~~~~~~~~~~~~~~^^^^^
  File "/usr/local/lib/python3.13/site-packages/starlette/routing.py", line 566, in __aenter__
    await self._router.startup()
  File "/usr/local/lib/python3.13/site-packages/starlette/routing.py", line 654, in startup
    await handler()
  File "/usr/local/lib/python3.13/site-packages/tortoise/contrib/fastapi/__init__.py", line 263, in init_orm
    await orm.init_orm()
  File "/usr/local/lib/python3.13/site-packages/tortoise/contrib/fastapi/__init__.py", line 138, in init_orm
    await Tortoise.init(
    ...<7 lines>...
    )
  File "/usr/local/lib/python3.13/site-packages/tortoise/__init__.py", line 512, in init
    await connections._init(connections_config, _create_db)
  File "/usr/local/lib/python3.13/site-packages/tortoise/connection.py", line 33, in _init
    await self._init_connections()
  File "/usr/local/lib/python3.13/site-packages/tortoise/connection.py", line 94, in _init_connections
    connection: "BaseDBAsyncClient" = self.get(alias)
                                      ~~~~~~~~^^^^^^^
  File "/usr/local/lib/python3.13/site-packages/tortoise/connection.py", line 124, in get
    connection: BaseDBAsyncClient = self._create_connection(conn_alias)
                                    ~~~~~~~~~~~~~~~~~~~~~~~^^^^^^^^^^^^
  File "/usr/local/lib/python3.13/site-packages/tortoise/connection.py", line 102, in _create_connection
    client_class = self._discover_client_class(db_info)
  File "/usr/local/lib/python3.13/site-packages/tortoise/connection.py", line 71, in _discover_client_class
    engine_module = importlib.import_module(engine_str)
  File "/usr/local/lib/python3.13/importlib/__init__.py", line 88, in import_module
    return _bootstrap._gcd_import(name[level:], package, level)
           ~~~~~~~~~~~~~~~~~~~~~~^^^^^^^^^^^^^^^^^^^^^^^^^^^^^^
  File "<frozen importlib._bootstrap>", line 1387, in _gcd_import
  File "<frozen importlib._bootstrap>", line 1360, in _find_and_load
  File "<frozen importlib._bootstrap>", line 1331, in _find_and_load_unlocked
  File "<frozen importlib._bootstrap>", line 935, in _load_unlocked
  File "<frozen importlib._bootstrap_external>", line 1026, in exec_module
  File "<frozen importlib._bootstrap>", line 488, in _call_with_frames_removed
  File "/usr/local/lib/python3.13/site-packages/tortoise/backends/asyncpg/__init__.py", line 1, in <module>
    from .client import AsyncpgDBClient
  File "/usr/local/lib/python3.13/site-packages/tortoise/backends/asyncpg/client.py", line 5, in <module>
    import asyncpg
ModuleNotFoundError: No module named 'asyncpg'

ERROR:    Application startup failed. Exiting.
(masclet-imperi) PS C:\Proyectos\claude\masclet-imperi-web\backend\docker\compose>
